2020-02-19 18:19:49 WARNING (Recorder) [homeassistant.components.recorder] Ended unfinished session (id=1 from 2020-02-19 22:50:49.285115)
2020-02-19 18:20:01 ERROR (MainThread) [metno] https://aa015h6buqvih86i1.api.met.no/weatherapi/locationforecast/1.9/ returned Cannot connect to host aa015h6buqvih86i1.api.met.no:443 ssl:None [Try again]
2020-02-19 18:20:01 ERROR (MainThread) [homeassistant.components.met.weather] Retrying in 16 minutes
2020-02-20 16:10:39 WARNING (MainThread) [homeassistant.components.http.ban] Login attempt or request with invalid authentication from 172.20.10.2
2020-02-20 16:27:07 ERROR (MainThread) [aiohttp.server] Error handling request
Traceback (most recent call last):
  File "/usr/local/lib/python3.7/site-packages/aiohttp/web_protocol.py", line 275, in data_received
    messages, upgraded, tail = self._request_parser.feed_data(data)
  File "aiohttp\_http_parser.pyx", line 523, in aiohttp._http_parser.HttpParser.feed_data
aiohttp.http_exceptions.BadStatusLine: invalid HTTP method
2020-02-20 16:27:08 ERROR (MainThread) [aiohttp.server] Error handling request
Traceback (most recent call last):
  File "/usr/local/lib/python3.7/site-packages/aiohttp/web_protocol.py", line 275, in data_received
    messages, upgraded, tail = self._request_parser.feed_data(data)
  File "aiohttp\_http_parser.pyx", line 523, in aiohttp._http_parser.HttpParser.feed_data
aiohttp.http_exceptions.BadStatusLine: invalid HTTP method
2020-02-20 16:27:09 ERROR (MainThread) [aiohttp.server] Error handling request
Traceback (most recent call last):
  File "/usr/local/lib/python3.7/site-packages/aiohttp/web_protocol.py", line 275, in data_received
    messages, upgraded, tail = self._request_parser.feed_data(data)
  File "aiohttp\_http_parser.pyx", line 523, in aiohttp._http_parser.HttpParser.feed_data
aiohttp.http_exceptions.BadStatusLine: invalid HTTP method
2020-02-20 16:27:10 ERROR (MainThread) [aiohttp.server] Error handling request
Traceback (most recent call last):
  File "/usr/local/lib/python3.7/site-packages/aiohttp/web_protocol.py", line 275, in data_received
    messages, upgraded, tail = self._request_parser.feed_data(data)
  File "aiohttp\_http_parser.pyx", line 523, in aiohttp._http_parser.HttpParser.feed_data
aiohttp.http_exceptions.BadStatusLine: invalid HTTP method
2020-02-20 16:27:10 ERROR (MainThread) [aiohttp.server] Error handling request
Traceback (most recent call last):
  File "/usr/local/lib/python3.7/site-packages/aiohttp/web_protocol.py", line 275, in data_received
    messages, upgraded, tail = self._request_parser.feed_data(data)
  File "aiohttp\_http_parser.pyx", line 523, in aiohttp._http_parser.HttpParser.feed_data
aiohttp.http_exceptions.BadStatusLine: invalid HTTP method
2020-02-20 16:27:11 ERROR (MainThread) [aiohttp.server] Error handling request
Traceback (most recent call last):
  File "/usr/local/lib/python3.7/site-packages/aiohttp/web_protocol.py", line 275, in data_received
    messages, upgraded, tail = self._request_parser.feed_data(data)
  File "aiohttp\_http_parser.pyx", line 523, in aiohttp._http_parser.HttpParser.feed_data
aiohttp.http_exceptions.BadStatusLine: invalid HTTP method
2020-02-20 16:27:12 ERROR (MainThread) [aiohttp.server] Error handling request
Traceback (most recent call last):
  File "/usr/local/lib/python3.7/site-packages/aiohttp/web_protocol.py", line 275, in data_received
    messages, upgraded, tail = self._request_parser.feed_data(data)
  File "aiohttp\_http_parser.pyx", line 523, in aiohttp._http_parser.HttpParser.feed_data
aiohttp.http_exceptions.BadStatusLine: invalid HTTP method
2020-02-20 16:27:13 ERROR (MainThread) [aiohttp.server] Error handling request
Traceback (most recent call last):
  File "/usr/local/lib/python3.7/site-packages/aiohttp/web_protocol.py", line 275, in data_received
    messages, upgraded, tail = self._request_parser.feed_data(data)
  File "aiohttp\_http_parser.pyx", line 523, in aiohttp._http_parser.HttpParser.feed_data
aiohttp.http_exceptions.BadStatusLine: invalid HTTP method
2020-02-20 16:39:19 ERROR (MainThread) [frontend.js.latest.202001303] http://172.20.10.4:8123/frontend_latest/chunk.21cca696221bd0b01d91.js:2038:1142 Expected '('
2020-02-20 16:57:20 ERROR (MainThread) [homeassistant.components.hassio] Invalid config for [http]: expected a dictionary for dictionary value @ data['http']. Got 'ip_ban_enabled'. (See ?, line ?). 
